Workbook

Sheet 功能清单（新架构）
A1: 序号 | B1: 一级模块 | C1: 二级功能 | D1: 功能说明 | E1: 冠麦对应功能 | F1: 处置 | G1: 优先级 | H1: 所属版本 | I1: 备注/关联
A2: 1 | B2: 1 工作台 | C2: 待办聚合带 | D2: 跨模块待办汇总，点击直达处理页 | E2: — | F2: 新增 | G2: P0 | H2: =IF($G2="P0","一期",IF($G2="P1","二期",IF($G2="P2","三期",IF($G2="并行","并行推进",IF($G2="待拍板","待定","不开发"))))) -> 一期
A3: 2 | B3: 1 工作台 | C3: 业务地图导航 | D3: 四层架构图即菜单：流动箭头、当前环节提示、待办角标 | E3: — | F3: 新增 | G3: P0 | H3: =IF($G3="P0","一期",IF($G3="P1","二期",IF($G3="P2","三期",IF($G3="并行","并行推进",IF($G3="待拍板","待定","不开发"))))) -> 一期 | I3: 首页形态随Q8
A4: 3 | B4: 1 工作台 | C4: 流程演示动画 | D4: 分步点亮四层与主线，培训与展厅通用 | E4: — | F4: 新增 | G4: P0 | H4: =IF($G4="P0","一期",IF($G4="P1","二期",IF($G4="P2","三期",IF($G4="并行","并行推进",IF($G4="待拍板","待定","不开发"))))) -> 一期
A5: 4 | B5: 1 工作台 | C5: 功能搜索直达 | D5: 按功能名搜索直达并高亮 | E5: — | F5: 新增 | G5: P0 | H5: =IF($G5="P0","一期",IF($G5="P1","二期",IF($G5="P2","三期",IF($G5="并行","并行推进",IF($G5="待拍板","待定","不开发"))))) -> 一期
A6: 5 | B6: 1 工作台 | C6: 新手引导 | D6: 聚光灯分步引导，可重播 | E6: — | F6: 新增 | G6: P0 | H6: =IF($G6="P0","一期",IF($G6="P1","二期",IF($G6="P2","三期",IF($G6="并行","并行推进",IF($G6="待拍板","待定","不开发"))))) -> 一期
A7: 6 | B7: 1 工作台 | C7: 消息通知 | D7: 审批与异常提醒 | E7: — | F7: 新增 | G7: P1 | H7: =IF($G7="P0","一期",IF($G7="P1","二期",IF($G7="P2","三期",IF($G7="并行","并行推进",IF($G7="待拍板","待定","不开发"))))) -> 二期
A8: 7 | B8: 2 基础档案 | C8: 企业信息/资质/配置 | D8: 企业基本资料与资质证照 | E8: 截图未提供（待补对照） | F8: 新增 | G8: P0 | H8: =IF($G8="P0","一期",IF($G8="P1","二期",IF($G8="P2","三期",IF($G8="并行","并行推进",IF($G8="待拍板","待定","不开发"))))) -> 一期 | I8: 冠麦系统设置板块未截图
A9: 8 | B9: 2 基础档案 | C9: 组织管理 | D9: 企业/门店/工厂/车间/生产线；产线自建供生产计划引用 | E9: 工厂模型（生产设置） | F9: 移位归并 | G9: P0 | H9: =IF($G9="P0","一期",IF($G9="P1","二期",IF($G9="P2","三期",IF($G9="并行","并行推进",IF($G9="待拍板","待定","不开发"))))) -> 一期
A10: 9 | B10: 2 基础档案 | C10: 员工档案 | D10: 员工基础信息；采购员并入（角色标识） | E10: 采购员（采购管理） | F10: 移位归并 | G10: P0 | H10: =IF($G10="P0","一期",IF($G10="P1","二期",IF($G10="P2","三期",IF($G10="并行","并行推进",IF($G10="待拍板","待定","不开发"))))) -> 一期
A11: 10 | B11: 2 基础档案 | C11: 账号/角色/审批权限 | D11: 账号开通、角色授权、审批权限 | E11: 截图未提供（待补对照） | F11: 新增 | G11: P0 | H11: =IF($G11="P0","一期",IF($G11="P1","二期",IF($G11="P2","三期",IF($G11="并行","并行推进",IF($G11="待拍板","待定","不开发"))))) -> 一期 | I11: 权限层级随Q6
A12: 11 | B12: 2 基础档案 | C12: 数据权限 | D12: 按组织/角色控制数据可见范围 | E12: 截图未提供 | F12: 新增 | G12: P1 | H12: =IF($G12="P0","一期",IF($G12="P1","二期",IF($G12="P2","三期",IF($G12="并行","并行推进",IF($G12="待拍板","待定","不开发"))))) -> 二期
A13: 12 | B13: 2 基础档案 | C13: 供应商档案 | D13: 供应商主数据与结算方式；采购只选用不修改 | E13: 供应商信息（采购-供应商管理） | F13: 移位归并 | G13: P0 | H13: =IF($G13="P0","一期",IF($G13="P1","二期",IF($G13="P2","三期",IF($G13="并行","并行推进",IF($G13="待拍板","待定","不开发"))))) -> 一期
A14: 13 | B14: 2 基础档案 | C14: 单据编号规则 | D14: 各类单据编号规则配置 | E14: 截图未提供 | F14: 新增 | G14: P0 | H14: =IF($G14="P0","一期",IF($G14="P1","二期",IF($G14="P2","三期",IF($G14="并行","并行推进",IF($G14="待拍板","待定","不开发"))))) -> 一期 | I14: 规则随Q5
A15: 14 | B15: 2 基础档案 | C15: 打印模板 | D15: 单据打印模板维护 | E15: 打印箱签为其一类（生产工具） | F15: 沿用 | G15: P0 | H15: =IF($G15="P0","一期",IF($G15="P1","二期",IF($G15="P2","三期",IF($G15="并行","并行推进",IF($G15="待拍板","待定","不开发"))))) -> 一期
A16: 15 | B16: 2 基础档案 | C16: 基础数据字典 | D16: 单位/类别等字典 | E16: 截图未提供 | F16: 新增 | G16: P0 | H16: =IF($G16="P0","一期",IF($G16="P1","二期",IF($G16="P2","三期",IF($G16="并行","并行推进",IF($G16="待拍板","待定","不开发"))))) -> 一期
A17: 16 | B17: 2 基础档案 | C17: 期初初始化 | D17: 商品池/BOM/客户/供应商/期初库存导入与校验 | E17: 截图未提供 | F17: 新增 | G17: P0 | H17: =IF($G17="P0","一期",IF($G17="P1","二期",IF($G17="P2","三期",IF($G17="并行","并行推进",IF($G17="待拍板","待定","不开发"))))) -> 一期
A18: 17 | B18: 2 基础档案 | C18: 审批流配置 | D18: 订单/对账/结款审批链 | E18: 截图未提供 | F18: 新增 | G18: P1 | H18: =IF($G18="P0","一期",IF($G18="P1","二期",IF($G18="P2","三期",IF($G18="并行","并行推进",IF($G18="待拍板","待定","不开发"))))) -> 二期
A19: 18 | B19: 3 商品/BOM | C19: 商品分类 | D19: 分类树维护 | E19: 商品分类（商品设置） | F19: 沿用 | G19: P0 | H19: =IF($G19="P0","一期",IF($G19="P1","二期",IF($G19="P2","三期",IF($G19="并行","并行推进",IF($G19="待拍板","待定","不开发"))))) -> 一期
A20: 19 | B20: 3 商品/BOM | C20: 商品单位 | D20: 计量单位维护 | E20: 商品列表内字段 | F20: 沿用 | G20: P0 | H20: =IF($G20="P0","一期",IF($G20="P1","二期",IF($G20="P2","三期",IF($G20="并行","并行推进",IF($G20="待拍板","待定","不开发"))))) -> 一期
A21: 20 | B21: 3 商品/BOM | C21: 商品税率 | D21: 税率维护（会议明确保留） | E21: 商品税率（商品设置） | F21: 沿用 | G21: P0 | H21: =IF($G21="P0","一期",IF($G21="P1","二期",IF($G21="P2","三期",IF($G21="并行","并行推进",IF($G21="待拍板","待定","不开发"))))) -> 一期
A22: 21 | B22: 3 商品/BOM | C22: 商品标签 | D22: 商品维度标签 | E22: — | F22: 新增 | G22: P1 | H22: =IF($G22="P0","一期",IF($G22="P1","二期",IF($G22="P2","三期",IF($G22="并行","并行推进",IF($G22="待拍板","待定","不开发"))))) -> 二期 | I22: 随Q10
A23: 22 | B23: 3 商品/BOM | C23: 商品档案（统一商品池） | D23: 原料/半成品/加工品/成品同池，分类筛选 | E23: 商品列表（商品管理） | F23: 沿用 | G23: P0 | H23: =IF($G23="P0","一期",IF($G23="P1","二期",IF($G23="P2","三期",IF($G23="并行","并行推进",IF($G23="待拍板","待定","不开发"))))) -> 一期
A24: 23 | B24: 3 商品/BOM | C24: 商品编码 | D24: 全局唯一（硬约束） | E24: 商品列表内 | F24: 沿用 | G24: P0 | H24: =IF($G24="P0","一期",IF($G24="P1","二期",IF($G24="P2","三期",IF($G24="并行","并行推进",IF($G24="待拍板","待定","不开发"))))) -> 一期
A25: 24 | B25: 3 商品/BOM | C25: 组合商品 | D25: 套餐类组合，对应BZ组合单 | E25: 组合商品（商品管理） | F25: 沿用 | G25: P0 | H25: =IF($G25="P0","一期",IF($G25="P1","二期",IF($G25="P2","三期",IF($G25="并行","并行推进",IF($G25="待拍板","待定","不开发"))))) -> 一期
A26: 25 | B26: 3 商品/BOM | C26: 生产BOM维护 | D26: 三级BOM＋出成率/损耗率，物料需求按其展开 | E26: 生产BOM管理（生产-BOM管理） | F26: 移位归并 | G26: P0 | H26: =IF($G26="P0","一期",IF($G26="P1","二期",IF($G26="P2","三期",IF($G26="并行","并行推进",IF($G26="待拍板","待定","不开发"))))) -> 一期 | I26: BOM归商品域
A27: 26 | B27: 3 商品/BOM | C27: 研发BOM | D27: 研发配方独立管理 | E27: 研发BOM管理（生产-BOM管理） | F27: 待确认 | G27: 待拍板 | H27: =IF($G27="P0","一期",IF($G27="P1","二期",IF($G27="P2","三期",IF($G27="并行","并行推进",IF($G27="待拍板","待定","不开发"))))) -> 待定 | I27: 会议未提；MVP建议先生产BOM
A28: 27 | B28: 3 商品/BOM | C28: 商品内标管理 | D28: 商品内部标识/条码 | E28: 商品内标管理（生产设置） | F28: 待确认 | G28: 待拍板 | H28: =IF($G28="P0","一期",IF($G28="P1","二期",IF($G28="P2","三期",IF($G28="并行","并行推进",IF($G28="待拍板","待定","不开发"))))) -> 待定 | I28: 会议未提
A29: 28 | B29: 3 商品/BOM | C29: 临时商品审批 | D29: — | E29: 临时商品审批（商品管理） | F29: 裁剪 | G29: 裁剪 | H29: =IF($G29="P0","一期",IF($G29="P1","二期",IF($G29="P2","三期",IF($G29="并行","并行推进",IF($G29="待拍板","待定","不开发"))))) -> 不开发 | I29: 07-06会议
A30: 29 | B30: 3 商品/BOM | C30: 替代商品（物料替换） | D30: — | E30: 替代商品（生产设置） | F30: 裁剪 | G30: 裁剪 | H30: =IF($G30="P0","一期",IF($G30="P1","二期",IF($G30="P2","三期",IF($G30="并行","并行推进",IF($G30="待拍板","待定","不开发"))))) -> 不开发 | I30: 07-06会议
A31: 30 | B31: 3 商品/BOM | C31: 价格管理体系 | D31: 客户报价单/协议价/历史报价整套 | E31: 客户报价单/客户协议价/历史报价（价格管理） | F31: 裁剪 | G31: 裁剪 | H31: =IF($G31="P0","一期",IF($G31="P1","二期",IF($G31="P2","三期",IF($G31="并行","并行推进",IF($G31="待拍板","待定","不开发"))))) -> 不开发 | I31: 07-06会议
A32: 31 | B32: 4 订单中心 | C32: 订单录入/导入 | D32: 手工录单＋Excel导入 | E32: 订单列表（新建/导入） | F32: 沿用 | G32: P0 | H32: =IF($G32="P0","一期",IF($G32="P1","二期",IF($G32="P2","三期",IF($G32="并行","并行推进",IF($G32="待拍板","待定","不开发"))))) -> 一期
A33: 32 | B33: 4 订单中心 | C33: 订单列表 | D33: 全部订单查询跟踪 | E33: 订单列表 | F33: 沿用 | G33: P0 | H33: =IF($G33="P0","一期",IF($G33="P1","二期",IF($G33="P2","三期",IF($G33="并行","并行推进",IF($G33="待拍板","待定","不开发"))))) -> 一期
A34: 33 | B34: 4 订单中心 | C34: 订单审核 | D34: 通过方可参与汇总，留痕 | E34: 订单审核 | F34: 沿用 | G34: P0 | H34: =IF($G34="P0","一期",IF($G34="P1","二期",IF($G34="P2","三期",IF($G34="并行","并行推进",IF($G34="待拍板","待定","不开发"))))) -> 一期
A35: 34 | B35: 4 订单中心 | C35: 订单汇总→转生产需求 | D35: 按交期汇总，一键转生产 | E35: （冠麦为生产计划内订单纳入） | F35: 沿用 | G35: P0 | H35: =IF($G35="P0","一期",IF($G35="P1","二期",IF($G35="P2","三期",IF($G35="并行","并行推进",IF($G35="待拍板","待定","不开发"))))) -> 一期 | I35: 汇总口径随决议
A36: 35 | B36: 4 订单中心 | C36: 订单分解 | D36: 按客户维度分解，与分拣投框联动 | E36: （由分拣进度/明细承接） | F36: 沿用 | G36: P1 | H36: =IF($G36="P0","一期",IF($G36="P1","二期",IF($G36="P2","三期",IF($G36="并行","并行推进",IF($G36="待拍板","待定","不开发"))))) -> 二期 | I36: 分解逻辑核对中
A37: 36 | B37: 4 订单中心 | C37: 订单对账→转财务 | D37: 对账审批通过流转财务结算 | E37: 对账审批 | F37: 沿用 | G37: P0 | H37: =IF($G37="P0","一期",IF($G37="P1","二期",IF($G37="P2","三期",IF($G37="并行","并行推进",IF($G37="待拍板","待定","不开发"))))) -> 一期
A38: 37 | B38: 4 订单中心 | C38: 订单变更 | D38: 已审订单变更与影响提示 | E38: 订单列表内操作 | F38: 沿用 | G38: P1 | H38: =IF($G38="P0","一期",IF($G38="P1","二期",IF($G38="P2","三期",IF($G38="并行","并行推进",IF($G38="待拍板","待定","不开发"))))) -> 二期
A39: 38 | B39: 4 订单中心 | C39: 预订单 | D39: 净配菜次日生产核心单据 | E39: 预订单 | F39: 待确认 | G39: 待拍板 | H39: =IF($G39="P0","一期",IF($G39="P1","二期",IF($G39="P2","三期",IF($G39="并行","并行推进",IF($G39="待拍板","待定","不开发"))))) -> 待定 | I39: Q1
A40: 39 | B40: 4 订单中心 | C40: 套账数据 | D40: 订单套账口径 | E40: 套账数据 | F40: 待确认 | G40: 待拍板 | H40: =IF($G40="P0","一期",IF($G40="P1","二期",IF($G40="P2","三期",IF($G40="并行","并行推进",IF($G40="待拍板","待定","不开发"))))) -> 待定 | I40: Q7 口径待明确
...

Sheet 冠麦原始功能去向
A1: 序号 | B1: 冠麦板块 | C1: 冠麦分组 | D1: 冠麦功能项 | E1: 新架构去向 | F1: 处置 | G1: 备注
A2: 1 | B2: 商品 | C2: 商品管理 | D2: 商品列表 | E2: 3 商品/BOM · 商品档案 | F2: 沿用
A3: 2 | B3: 商品 | C3: 商品管理 | D3: 组合商品 | E3: 3 商品/BOM · 组合商品 | F3: 沿用
A4: 3 | B4: 商品 | C4: 商品管理 | D4: 临时商品审批 | E4: — | F4: 裁剪 | G4: 07-06会议
A5: 4 | B5: 商品 | C5: 价格管理 | D5: 客户报价单 | E5: — | F5: 裁剪 | G5: 价格体系整套后置
A6: 5 | B6: 商品 | C6: 价格管理 | D6: 客户协议价 | E6: — | F6: 裁剪
A7: 6 | B7: 商品 | C7: 价格管理 | D7: 历史报价 | E7: — | F7: 裁剪
A8: 7 | B8: 商品 | C8: 商品设置 | D8: 商品分类 | E8: 3 商品/BOM · 商品分类 | F8: 沿用
A9: 8 | B9: 商品 | C9: 商品设置 | D9: 商品税率 | E9: 3 商品/BOM · 商品税率 | F9: 沿用
A10: 9 | B10: 订单 | C10: 订单管理 | D10: 订单列表 | E10: 4 订单中心 · 订单列表/录入/导入 | F10: 沿用
A11: 10 | B11: 订单 | C11: 订单管理 | D11: 预订单 | E11: 4 订单中心 · 预订单 | F11: 待确认 | G11: Q1
A12: 11 | B12: 订单 | C12: 订单管理 | D12: 套账数据 | E12: 4 订单中心 · 套账数据 | F12: 待确认 | G12: Q7 口径待明确
A13: 12 | B13: 订单 | C13: 订单管理 | D13: 菜谱下单 | E13: — | F13: 裁剪
A14: 13 | B14: 订单 | C14: 订单管理 | D14: 未下单客户 | E14: — | F14: 裁剪
A15: 14 | B15: 订单 | C15: 订单管理 | D15: 订单审核 | E15: 4 订单中心 · 订单审核 | F15: 沿用
A16: 15 | B16: 订单 | C16: 订单管理 | D16: 对账审批 | E16: 4 订单中心 · 订单对账→转财务 | F16: 沿用
A17: 16 | B17: 订单 | C17: 售后 | D17: 售后列表 | E17: 4 订单中心 · 售后列表 | F17: 延后 | G17: 暂缓后做
A18: 17 | B18: 订单 | C18: 售后 | D18: 取货任务 | E18: 9 分拣配送 · 拣货 | F18: 待确认 | G18: Q7 与分解取货关系
A19: 18 | B19: 采购 | C19: 采购管理 | D19: 采购计划 | E19: 5 采购中心 · 统一采购单 | F19: 合并整合 | G19: 三合一
A20: 19 | B20: 采购 | C20: 采购管理 | D20: 补采 | E20: 5 · 统一采购单 | F20: 合并整合
A21: 20 | B21: 采购 | C21: 采购管理 | D21: 代采单 | E21: 5 · 代采单 | F21: 待确认 | G21: 会议未提及
A22: 21 | B22: 采购 | C22: 采购管理 | D22: 采购单据 | E22: 5 · 统一采购单 | F22: 合并整合
A23: 22 | B23: 采购 | C23: 采购管理 | D23: 采购员 | E23: 2 基础档案 · 员工档案 | F23: 移位归并 | G23: 角色标识
A24: 23 | B24: 采购 | C24: 采购管理 | D24: 询价记录 | E24: — | F24: 裁剪
A25: 24 | B25: 采购 | C25: 采购管理 | D25: 采购协议价 | E25: — | F25: 裁剪
A26: 25 | B26: 采购 | C26: 采购管理 | D26: 询价单 | E26: — | F26: 裁剪
A27: 26 | B27: 采购 | C27: 采购管理 | D27: 结款审批 | E27: 5 · 结款审批 | F27: 沿用
A28: 27 | B28: 采购 | C28: 采购规则 | D28: 采购计划规则 | E28: — | F28: 裁剪
A29: 28 | B29: 采购 | C29: 采购规则 | D29: 供货比例 | E29: — | F29: 裁剪
A30: 29 | B30: 采购 | C30: 供应商管理 | D30: 供应商信息 | E30: 2 基础档案 · 供应商档案 | F30: 移位归并
A31: 30 | B31: 采购 | C31: 质检管理 | D31: 检测报告 | E31: 5 · 检测报告（联动8质检溯源） | F31: 沿用
A32: 31 | B32: 库存 | C32: 入库管理 | D32: 采购入库单 | E32: 6 库存中心 · 入库单 | F32: 合并整合
A33: 32 | B33: 库存 | C33: 入库管理 | D33: 销售退货入库单 | E33: 6 · 退货类单据 | F33: 延后 | G33: 随售后
A34: 33 | B34: 库存 | C34: 入库管理 | D34: 其他入库单 | E34: 6 · 入库单 | F34: 合并整合
A35: 34 | B35: 库存 | C35: 入库管理 | D35: 其他退货入库单 | E35: 6 · 退货类单据 | F35: 延后
A36: 35 | B36: 库存 | C36: 出库管理 | D36: 采购退货出库单 | E36: 6 · 退货类单据 | F36: 待确认 | G36: 建议P1
A37: 36 | B37: 库存 | C37: 出库管理 | D37: 销售出库单 | E37: 6 · 出库单 | F37: 合并整合
A38: 37 | B38: 库存 | C38: 出库管理 | D38: 其他出库单 | E38: 6 · 出库单 | F38: 合并整合
A39: 38 | B39: 库存 | C39: 出库管理 | D39: 其他退货出库单 | E39: 6 · 退货类单据 | F39: 延后
A40: 39 | B40: 库存 | C40: 盘点管理 | D40: 盘点任务 | E40: 6 · 库存盘点 | F40: 沿用
...

Sheet 汇总
A1: 一级模块 | B1: P0 | C1: P1 | D1: P2 | E1: 并行 | F1: 待拍板 | G1: 裁剪 | H1: 功能合计 | I1: 开发范围小计
A2: 1 工作台 | B2: =COUNTIFS('功能清单（新架构）'!$B:$B,$A2,'功能清单（新架构）'!$G:$G,B$1) -> 5 | C2: =COUNTIFS('功能清单（新架构）'!$B:$B,$A2,'功能清单（新架构）'!$G:$G,C$1) -> 1 | D2: =COUNTIFS('功能清单（新架构）'!$B:$B,$A2,'功能清单（新架构）'!$G:$G,D$1) -> 0 | E2: =COUNTIFS('功能清单（新架构）'!$B:$B,$A2,'功能清单（新架构）'!$G:$G,E$1) -> 0 | F2: =COUNTIFS('功能清单（新架构）'!$B:$B,$A2,'功能清单（新架构）'!$G:$G,F$1) -> 0 | G2: =COUNTIFS('功能清单（新架构）'!$B:$B,$A2,'功能清单（新架构）'!$G:$G,G$1) -> 0 | H2: =SUM(B2:G2) -> 6 | I2: =H2-G2 -> 6
A3: 2 基础档案 | B3: =COUNTIFS('功能清单（新架构）'!$B:$B,$A3,'功能清单（新架构）'!$G:$G,B$1) -> 9 | C3: =COUNTIFS('功能清单（新架构）'!$B:$B,$A3,'功能清单（新架构）'!$G:$G,C$1) -> 2 | D3: =COUNTIFS('功能清单（新架构）'!$B:$B,$A3,'功能清单（新架构）'!$G:$G,D$1) -> 0 | E3: =COUNTIFS('功能清单（新架构）'!$B:$B,$A3,'功能清单（新架构）'!$G:$G,E$1) -> 0 | F3: =COUNTIFS('功能清单（新架构）'!$B:$B,$A3,'功能清单（新架构）'!$G:$G,F$1) -> 0 | G3: =COUNTIFS('功能清单（新架构）'!$B:$B,$A3,'功能清单（新架构）'!$G:$G,G$1) -> 0 | H3: =SUM(B3:G3) -> 11 | I3: =H3-G3 -> 11
A4: 3 商品/BOM | B4: =COUNTIFS('功能清单（新架构）'!$B:$B,$A4,'功能清单（新架构）'!$G:$G,B$1) -> 7 | C4: =COUNTIFS('功能清单（新架构）'!$B:$B,$A4,'功能清单（新架构）'!$G:$G,C$1) -> 1 | D4: =COUNTIFS('功能清单（新架构）'!$B:$B,$A4,'功能清单（新架构）'!$G:$G,D$1) -> 0 | E4: =COUNTIFS('功能清单（新架构）'!$B:$B,$A4,'功能清单（新架构）'!$G:$G,E$1) -> 0 | F4: =COUNTIFS('功能清单（新架构）'!$B:$B,$A4,'功能清单（新架构）'!$G:$G,F$1) -> 2 | G4: =COUNTIFS('功能清单（新架构）'!$B:$B,$A4,'功能清单（新架构）'!$G:$G,G$1) -> 3 | H4: =SUM(B4:G4) -> 13 | I4: =H4-G4 -> 10
A5: 4 订单中心 | B5: =COUNTIFS('功能清单（新架构）'!$B:$B,$A5,'功能清单（新架构）'!$G:$G,B$1) -> 5 | C5: =COUNTIFS('功能清单（新架构）'!$B:$B,$A5,'功能清单（新架构）'!$G:$G,C$1) -> 2 | D5: =COUNTIFS('功能清单（新架构）'!$B:$B,$A5,'功能清单（新架构）'!$G:$G,D$1) -> 1 | E5: =COUNTIFS('功能清单（新架构）'!$B:$B,$A5,'功能清单（新架构）'!$G:$G,E$1) -> 0 | F5: =COUNTIFS('功能清单（新架构）'!$B:$B,$A5,'功能清单（新架构）'!$G:$G,F$1) -> 2 | G5: =COUNTIFS('功能清单（新架构）'!$B:$B,$A5,'功能清单（新架构）'!$G:$G,G$1) -> 3 | H5: =SUM(B5:G5) -> 13 | I5: =H5-G5 -> 10
A6: 5 采购中心 | B6: =COUNTIFS('功能清单（新架构）'!$B:$B,$A6,'功能清单（新架构）'!$G:$G,B$1) -> 0 | C6: =COUNTIFS('功能清单（新架构）'!$B:$B,$A6,'功能清单（新架构）'!$G:$G,C$1) -> 5 | D6: =COUNTIFS('功能清单（新架构）'!$B:$B,$A6,'功能清单（新架构）'!$G:$G,D$1) -> 0 | E6: =COUNTIFS('功能清单（新架构）'!$B:$B,$A6,'功能清单（新架构）'!$G:$G,E$1) -> 0 | F6: =COUNTIFS('功能清单（新架构）'!$B:$B,$A6,'功能清单（新架构）'!$G:$G,F$1) -> 1 | G6: =COUNTIFS('功能清单（新架构）'!$B:$B,$A6,'功能清单（新架构）'!$G:$G,G$1) -> 2 | H6: =SUM(B6:G6) -> 8 | I6: =H6-G6 -> 6
A7: 6 库存中心 | B7: =COUNTIFS('功能清单（新架构）'!$B:$B,$A7,'功能清单（新架构）'!$G:$G,B$1) -> 0 | C7: =COUNTIFS('功能清单（新架构）'!$B:$B,$A7,'功能清单（新架构）'!$G:$G,C$1) -> 4 | D7: =COUNTIFS('功能清单（新架构）'!$B:$B,$A7,'功能清单（新架构）'!$G:$G,D$1) -> 3 | E7: =COUNTIFS('功能清单（新架构）'!$B:$B,$A7,'功能清单（新架构）'!$G:$G,E$1) -> 0 | F7: =COUNTIFS('功能清单（新架构）'!$B:$B,$A7,'功能清单（新架构）'!$G:$G,F$1) -> 3 | G7: =COUNTIFS('功能清单（新架构）'!$B:$B,$A7,'功能清单（新架构）'!$G:$G,G$1) -> 3 | H7: =SUM(B7:G7) -> 13 | I7: =H7-G7 -> 10
A8: 7 生产中心 | B8: =COUNTIFS('功能清单（新架构）'!$B:$B,$A8,'功能清单（新架构）'!$G:$G,B$1) -> 10 | C8: =COUNTIFS('功能清单（新架构）'!$B:$B,$A8,'功能清单（新架构）'!$G:$G,C$1) -> 3 | D8: =COUNTIFS('功能清单（新架构）'!$B:$B,$A8,'功能清单（新架构）'!$G:$G,D$1) -> 1 | E8: =COUNTIFS('功能清单（新架构）'!$B:$B,$A8,'功能清单（新架构）'!$G:$G,E$1) -> 0 | F8: =COUNTIFS('功能清单（新架构）'!$B:$B,$A8,'功能清单（新架构）'!$G:$G,F$1) -> 2 | G8: =COUNTIFS('功能清单（新架构）'!$B:$B,$A8,'功能清单（新架构）'!$G:$G,G$1) -> 3 | H8: =SUM(B8:G8) -> 19 | I8: =H8-G8 -> 16
A9: 8 质检溯源 | B9: =COUNTIFS('功能清单（新架构）'!$B:$B,$A9,'功能清单（新架构）'!$G:$G,B$1) -> 0 | C9: =COUNTIFS('功能清单（新架构）'!$B:$B,$A9,'功能清单（新架构）'!$G:$G,C$1) -> 6 | D9: =COUNTIFS('功能清单（新架构）'!$B:$B,$A9,'功能清单（新架构）'!$G:$G,D$1) -> 1 | E9: =COUNTIFS('功能清单（新架构）'!$B:$B,$A9,'功能清单（新架构）'!$G:$G,E$1) -> 0 | F9: =COUNTIFS('功能清单（新架构）'!$B:$B,$A9,'功能清单（新架构）'!$G:$G,F$1) -> 0 | G9: =COUNTIFS('功能清单（新架构）'!$B:$B,$A9,'功能清单（新架构）'!$G:$G,G$1) -> 0 | H9: =SUM(B9:G9) -> 7 | I9: =H9-G9 -> 7
A10: 9 分拣配送 | B10: =COUNTIFS('功能清单（新架构）'!$B:$B,$A10,'功能清单（新架构）'!$G:$G,B$1) -> 0 | C10: =COUNTIFS('功能清单（新架构）'!$B:$B,$A10,'功能清单（新架构）'!$G:$G,C$1) -> 8 | D10: =COUNTIFS('功能清单（新架构）'!$B:$B,$A10,'功能清单（新架构）'!$G:$G,D$1) -> 2 | E10: =COUNTIFS('功能清单（新架构）'!$B:$B,$A10,'功能清单（新架构）'!$G:$G,E$1) -> 0 | F10: =COUNTIFS('功能清单（新架构）'!$B:$B,$A10,'功能清单（新架构）'!$G:$G,F$1) -> 1 | G10: =COUNTIFS('功能清单（新架构）'!$B:$B,$A10,'功能清单（新架构）'!$G:$G,G$1) -> 2 | H10: =SUM(B10:G10) -> 13 | I10: =H10-G10 -> 11
A11: 10 客户中心 | B11: =COUNTIFS('功能清单（新架构）'!$B:$B,$A11,'功能清单（新架构）'!$G:$G,B$1) -> 3 | C11: =COUNTIFS('功能清单（新架构）'!$B:$B,$A11,'功能清单（新架构）'!$G:$G,C$1) -> 2 | D11: =COUNTIFS('功能清单（新架构）'!$B:$B,$A11,'功能清单（新架构）'!$G:$G,D$1) -> 0 | E11: =COUNTIFS('功能清单（新架构）'!$B:$B,$A11,'功能清单（新架构）'!$G:$G,E$1) -> 0 | F11: =COUNTIFS('功能清单（新架构）'!$B:$B,$A11,'功能清单（新架构）'!$G:$G,F$1) -> 0 | G11: =COUNTIFS('功能清单（新架构）'!$B:$B,$A11,'功能清单（新架构）'!$G:$G,G$1) -> 2 | H11: =SUM(B11:G11) -> 7 | I11: =H11-G11 -> 5
A12: 11 财务中心 | B12: =COUNTIFS('功能清单（新架构）'!$B:$B,$A12,'功能清单（新架构）'!$G:$G,B$1) -> 0 | C12: =COUNTIFS('功能清单（新架构）'!$B:$B,$A12,'功能清单（新架构）'!$G:$G,C$1) -> 3 | D12: =COUNTIFS('功能清单（新架构）'!$B:$B,$A12,'功能清单（新架构）'!$G:$G,D$1) -> 2 | E12: =COUNTIFS('功能清单（新架构）'!$B:$B,$A12,'功能清单（新架构）'!$G:$G,E$1) -> 0 | F12: =COUNTIFS('功能清单（新架构）'!$B:$B,$A12,'功能清单（新架构）'!$G:$G,F$1) -> 3 | G12: =COUNTIFS('功能清单（新架构）'!$B:$B,$A12,'功能清单（新架构）'!$G:$G,G$1) -> 1 | H12: =SUM(B12:G12) -> 9 | I12: =H12-G12 -> 8
A13: 12 报表中心 | B13: =COUNTIFS('功能清单（新架构）'!$B:$B,$A13,'功能清单（新架构）'!$G:$G,B$1) -> 0 | C13: =COUNTIFS('功能清单（新架构）'!$B:$B,$A13,'功能清单（新架构）'!$G:$G,C$1) -> 0 | D13: =COUNTIFS('功能清单（新架构）'!$B:$B,$A13,'功能清单（新架构）'!$G:$G,D$1) -> 8 | E13: =COUNTIFS('功能清单（新架构）'!$B:$B,$A13,'功能清单（新架构）'!$G:$G,E$1) -> 0 | F13: =COUNTIFS('功能清单（新架构）'!$B:$B,$A13,'功能清单（新架构）'!$G:$G,F$1) -> 1 | G13: =COUNTIFS('功能清单（新架构）'!$B:$B,$A13,'功能清单（新架构）'!$G:$G,G$1) -> 1 | H13: =SUM(B13:G13) -> 10 | I13: =H13-G13 -> 9
... A15: 14 应用市场 | B15: =COUNTIFS('功能清单（新架构）'!$B:$B,$A15,'功能清单（新架构）'!$G:$G,B$1) -> 0 | C15: =COUNTIFS('功能清单（新架构）'!$B:$B,$A15,'功能清单（新架构）'!$G:$G,C$1) -> 0 | D15: =COUNTIFS('功能清单（新架构）'!$B:$B,$A15,'功能清单（新架构）'!$G:$G,D$1) -> 3 | E15: =COUNTIFS('功能清单（新架构）'!$B:$B,$A15,'功能清单（新架构）'!$G:$G,E$1) -> 2 | F15: =COUNTIFS('功能清单（新架构）'!$B:$B,$A15,'功能清单（新架构）'!$G:$G,F$1) -> 0 | G15: =COUNTIFS('功能清单（新架构）'!$B:$B,$A15,'功能清单（新架构）'!$G:$G,G$1) -> 0 | H15: =SUM(B15:G15) -> 5 | I15: =H15-G15 -> 5
A16: 合计 | B16: =SUM(B2:B15) -> 39 | C16: =SUM(C2:C15) -> 37 | D16: =SUM(D2:D15) -> 29 | E16: =SUM(E2:E15) -> 2 | F16: =SUM(F2:F15) -> 15 | G16: =SUM(G2:G15) -> 20 | H16: =SUM(H2:H15) -> 142 | I16: =SUM(I2:I15) -> 122
A18: 冠麦功能处置统计（共 121 项，来自10张截图）
B19: 沿用 | C19: 合并整合 | D19: 移位归并 | E19: 裁剪 | F19: 延后 | G19: 待确认 | H19: 合计
B20: =COUNTIF(冠麦原始功能去向!$F:$F,B19) -> 35 | C20: =COUNTIF(冠麦原始功能去向!$F:$F,C19) -> 10 | D20: =COUNTIF(冠麦原始功能去向!$F:$F,D19) -> 5 | E20: =COUNTIF(冠麦原始功能去向!$F:$F,E19) -> 20 | F20: =COUNTIF(冠麦原始功能去向!$F:$F,F19) -> 30 | G20: =COUNTIF(冠麦原始功能去向!$F:$F,G19) -> 21 | H20: =SUM(B20:G20) -> 121
A22: 处置定义：沿用=直接保留｜合并整合=多项合一｜移位归并=换模块归属｜裁剪=07-06会议已定不做｜延后=P2后置｜待确认=会议未提或口径矛盾，进拍板清单
A23: 本版新发现待拍板项（冠麦有、会议未提）：代采单、组装拆卸单、退料管理、研发BOM、商品内标、打印箱签、拣货计划/记录、费用单/收入单、流水提现、项目点报表、占用/待出库分布、退货类单据
A24: 冠麦截图缺失板块：基础档案/系统设置、权限、客户——对照待补，相关行标注“截图未提供”
A25: 口径来源：07-06会议纪要、PRD v0.9、冠麦系统截图（2026-07-09提供）；Q编号见PRD第7章与《第一次产品讨论包》
